Workbook

Sheet Losetas
A1: Código | B1: Número | C1: Cod. Tamaño | D1: Tamaño | E1: Tile Set | F1: Cara A | G1: Cara B
A2: =IF(C2<>"",CONCATENATE(B2,"A/",C2),"") -> 1A/a | B2: 1 | C2: =VLOOKUP(D2, Datos!$B$3:$C$13, 2, FALSE()) -> a | D2: 10x8 | E2: 1 | F2: Mazmorra | G2: Bosque (camino)
A3: =IF(C3<>"",CONCATENATE(B3,"A/",C3),"") -> 2A/a | B3: 2 | C3: =VLOOKUP(D3, Datos!$B$3:$C$13, 2, FALSE()) -> a | D3: 10x8 | E3: 1 | F3: Mazmorra (chimenea) | G3: Bosque (camino)
A4: =IF(C4<>"",CONCATENATE(B4,"A/",C4),"") -> 3A/e | B4: 3 | C4: =VLOOKUP(D4, Datos!$B$3:$C$13, 2, FALSE()) -> e | D4: 6x2 | E4: 1 | F4: Mazmorra (serpiente) | G4: Mazmorra (telarañas)
A5: =IF(C5<>"",CONCATENATE(B5,"A/",C5),"") -> 4A/e | B5: 4 | C5: =VLOOKUP(D5, Datos!$B$3:$C$13, 2, FALSE()) -> e | D5: 6x2 | E5: 1 | F5: Mazmorra (murciélago) | G5: Enredaderas
A6: =IF(C6<>"",CONCATENATE(B6,"A/",C6),"") -> 5A/c | B6: 5 | C6: =VLOOKUP(D6, Datos!$B$3:$C$13, 2, FALSE()) -> c | D6: 6x6 | E6: 1 | F6: Mazmorra | G6: Mazmorra círculo mágico
A7: =IF(C7<>"",CONCATENATE(B7,"A/",C7),"") -> 6A/c | B7: 6 | C7: =VLOOKUP(D7, Datos!$B$3:$C$13, 2, FALSE()) -> c | D7: 6x6 | E7: 1 | F7: Cripta | G7: Mazmorra escalera
A8: =IF(C8<>"",CONCATENATE(B8,"A/",C8),"") -> 7A/c | B8: 7 | C8: =VLOOKUP(D8, Datos!$B$3:$C$13, 2, FALSE()) -> c | D8: 6x6 | E8: 1 | F8: Mazmorra rúnica | G8: Estancia madera
A9: =IF(C9<>"",CONCATENATE(B9,"A/",C9),"") -> 8A/c | B9: 8 | C9: =VLOOKUP(D9, Datos!$B$3:$C$13, 2, FALSE()) -> c | D9: 6x6 | E9: 1 | F9: Mazmorra circular | G9: Estancia doble
A10: =IF(C10<>"",CONCATENATE(B10,"A/",C10),"") -> 10A/g | B10: 10 | C10: =VLOOKUP(D10, Datos!$B$3:$C$13, 2, FALSE()) -> g | D10: 6x1 | E10: 1 | F10: Mazmorra | G10: Mazmorra (desnivel)
A11: =IF(C11<>"",CONCATENATE(B11,"A/",C11),"") -> 11A/g | B11: 11 | C11: =VLOOKUP(D11, Datos!$B$3:$C$13, 2, FALSE()) -> g | D11: 6x1 | E11: 1 | F11: Mazmorra | G11: Pasarela
A12: =IF(C12<>"",CONCATENATE(B12,"A/",C12),"") -> 12A/c | B12: 12 | C12: =VLOOKUP(D12, Datos!$B$3:$C$13, 2, FALSE()) -> c | D12: 6x6 | E12: 1 | F12: Mazmorra | G12: Cocina
A13: =IF(C13<>"",CONCATENATE(B13,"A/",C13),"") -> 13A/c | B13: 13 | C13: =VLOOKUP(D13, Datos!$B$3:$C$13, 2, FALSE()) -> c | D13: 6x6 | E13: 1 | F13: Mazmorra | G13: Abismo
... A115: =IF(C115<>"",CONCATENATE(B115,"A/",C115),"") -> 122A/i | B115: 122 | C115: =VLOOKUP(D115, Datos!$B$3:$C$13, 2, FALSE()) -> i | D115: 2x2 | E115: 3 | F115: Roca nieve | G115: Pino nieve
A116: =IF(C116<>"",CONCATENATE(B116,"A/",C116),"") | D116: 2x1 | E116: 2 | F116: Estalagmita | G116: Estalagmita
A117: =IF(C117<>"",CONCATENATE(B117,"A/",C117),"") | D117: 2x1 | E117: 2 | F117: Estalagmita | G117: Estalagmita
A118: =IF(C118<>"",CONCATENATE(B118,"A/",C118),"") | D118: 2x1 | E118: 2 | F118: Estalagmita | G118: Estalagmita
A119: =IF(C119<>"",CONCATENATE(B119,"A/",C119),"") | D119: 2x1 | E119: 2 | F119: Estalagmita | G119: Cueva
A120: =IF(C120<>"",CONCATENATE(B120,"A/",C120),"") | D120: 2x1 | E120: 2 | F120: Estalagmita | G120: Cueva
A121: =IF(C121<>"",CONCATENATE(B121,"A/",C121),"") | D121: 2x1 | E121: 2 | F121: Estalagmita | G121: Cueva
A122: =IF(C122<>"",CONCATENATE(B122,"A/",C122),"") | D122: 2x1 | E122: 2 | F122: Cloacas | G122: Cloacas
A123: =IF(C123<>"",CONCATENATE(B123,"A/",C123),"") | D123: 2x1 | E123: 2 | F123: Cloacas | G123: Cloacas
A124: =IF(C124<>"",CONCATENATE(B124,"A/",C124),"") | D124: 2x1 | E124: 2 | F124: Cloacas | G124: Cloacas
A125: =IF(C125<>"",CONCATENATE(B125,"A/",C125),"") | D125: 2x1 | E125: 1 | F125: Pasarela madera | G125: Mazmorra
A126: =IF(C126<>"",CONCATENATE(B126,"A/",C126),"") | D126: 2x1 | E126: 1 | F126: Pasarela madera | G126: Mazmorra
A127: =IF(C127<>"",CONCATENATE(B127,"A/",C127),"") | D127: 2x1 | E127: 1 | F127: Pasarela madera | G127: Mazmorra
... A149: =IF(C149<>"",CONCATENATE(B149,"A/",C149),"") | D149: 2x1 | E149: 1 | F149: Caballo (blanco) | G149: Mazmorra
D150: 2x1 | E150: 1 | F150: Caballo (blanco) | G150: Mazmorra
A151: =IF(C151<>"",CONCATENATE(B151,"A/",C151),"") | D151: 2x1 | E151: 1 | F151: Caballo (negro) | G151: Mazmorra
A152: =IF(C152<>"",CONCATENATE(B152,"A/",C152),"") | D152: 2x1 | E152: 1 | F152: Caballo (negro) | G152: Mazmorra
A153: =IF(C153<>"",CONCATENATE(B153,"A/",C153),"") | D153: 2x1 | E153: 1 | F153: Forja | G153: Mazmorra
A154: =IF(C154<>"",CONCATENATE(B154,"A/",C154),"") | D154: 2x1 | E154: 1 | F154: Cocina (mesa) | G154: Mazmorra
A155: =IF(C155<>"",CONCATENATE(B155,"A/",C155),"") | D155: 2x1 | E155: 1 | F155: Tumba | G155: Mazmorra
A156: =IF(C156<>"",CONCATENATE(B156,"A/",C156),"") | D156: 2x1 | E156: 1 | F156: Tumba | G156: Mazmorra
A157: =IF(C157<>"",CONCATENATE(B157,"A/",C157),"") | D157: 2x1 | E157: 1 | F157: Tumba | G157: Mazmorra
A158: =IF(C158<>"",CONCATENATE(B158,"A/",C158),"") | D158: 2x1 | E158: 1 | F158: Rejilla | G158: Mazmorra
A159: =IF(C159<>"",CONCATENATE(B159,"A/",C159),"") | D159: 2x1 | E159: 1 | F159: Armería (mesa) | G159: Mazmorra
A160: =IF(C160<>"",CONCATENATE(B160,"A/",C160),"") | D160: 2x1 | E160: 1 | F160: Muro de fuego | G160: Mazmorra
A161: =IF(C161<>"",CONCATENATE(B161,"A/",C161),"") | D161: 2x1 | E161: 1 | F161: Veta de cristal | G161: Mazmorra
A162: =IF(C162<>"",CONCATENATE(B162,"A/",C162),"") | D162: 2x1 | E162: 1 | F162: Niebla misteriosa | G162: Mazmorra
...

Sheet Datos
B2: Tamaño | C2: Cod. Tamaño
B3: 10x8 | C3: a
B4: 10x4 | C4: b
B5: 6x6 | C5: c
B6: 6x4 | C6: d
B7: 4x4 | C7: d
B8: 6x2 | C8: e
B9: 4x2 | C9: f
B10: 3x3 | C10: f
B11: 6x1 | C11: g
B12: 3x2 | C12: h
B13: 2x2 | C13: i
B14: 2x1
B15: 1x1
